2018-02-23 19:25:05,168 INFO org.apache.hadoop.yarn.server.resourcemanager.ResourceManager: STARTUP_MSG: 
/************************************************************
STARTUP_MSG: Starting ResourceManager
STARTUP_MSG:   host = ustc-optiplex-7050/127.0.1.1
STARTUP_MSG:   args = []
STARTUP_MSG:   version = 2.7.2
STARTUP_MSG:   build = https://git-wip-us.apache.org/repos/asf/hadoop.git -r b165c4fe8a74265c792ce23f546c64604acf0e41; compiled by 'jenkins' on 2016-01-26T00:08Z
STARTUP_MSG:   java = 1.8.0_161
************************************************************/
2018-02-23 19:25:05,174 INFO org.apache.hadoop.yarn.server.resourcemanager.ResourceManager: registered UNIX signal handlers for [TERM, HUP, INT]
2018-02-23 19:25:05,328 INFO org.apache.hadoop.conf.Configuration: found resource core-site.xml at file:/opt/hadoop-2.7.2/etc/hadoop/core-site.xml
2018-02-23 19:25:05,374 INFO org.apache.hadoop.security.Groups: clearing userToGroupsMap cache
2018-02-23 19:25:05,416 INFO org.apache.hadoop.conf.Configuration: found resource yarn-site.xml at file:/opt/hadoop-2.7.2/etc/hadoop/yarn-site.xml
2018-02-23 19:25:05,507 INFO org.apache.hadoop.yarn.event.AsyncDispatcher: Registering class org.apache.hadoop.yarn.server.resourcemanager.RMFatalEventType for class org.apache.hadoop.yarn.server.resourcemanager.ResourceManager$RMFatalEventDispatcher
2018-02-23 19:25:05,644 INFO org.apache.hadoop.yarn.server.resourcemanager.security.NMTokenSecretManagerInRM: NMTokenKeyRollingInterval: 86400000ms and NMTokenKeyActivationDelay: 900000ms
2018-02-23 19:25:05,646 INFO org.apache.hadoop.yarn.server.resourcemanager.security.RMContainerTokenSecretManager: ContainerTokenKeyRollingInterval: 86400000ms and ContainerTokenKeyActivationDelay: 900000ms
2018-02-23 19:25:05,648 INFO org.apache.hadoop.yarn.server.resourcemanager.security.AMRMTokenSecretManager: AMRMTokenKeyRollingInterval: 86400000ms and AMRMTokenKeyActivationDelay: 900000 ms
2018-02-23 19:25:05,665 INFO org.apache.hadoop.yarn.event.AsyncDispatcher: Registering class org.apache.hadoop.yarn.server.resourcemanager.recovery.RMStateStoreEventType for class org.apache.hadoop.yarn.server.resourcemanager.recovery.RMStateStore$ForwardingEventHandler
2018-02-23 19:25:05,666 INFO org.apache.hadoop.yarn.event.AsyncDispatcher: Registering class org.apache.hadoop.yarn.server.resourcemanager.NodesListManagerEventType for class org.apache.hadoop.yarn.server.resourcemanager.NodesListManager
2018-02-23 19:25:05,666 INFO org.apache.hadoop.yarn.server.resourcemanager.ResourceManager: Using Scheduler: org.apache.hadoop.yarn.server.resourcemanager.scheduler.capacity.CapacityScheduler
2018-02-23 19:25:05,678 INFO org.apache.hadoop.yarn.event.AsyncDispatcher: Registering class org.apache.hadoop.yarn.server.resourcemanager.scheduler.event.SchedulerEventType for class org.apache.hadoop.yarn.server.resourcemanager.ResourceManager$SchedulerEventDispatcher
2018-02-23 19:25:05,678 INFO org.apache.hadoop.yarn.event.AsyncDispatcher: Registering class org.apache.hadoop.yarn.server.resourcemanager.rmapp.RMAppEventType for class org.apache.hadoop.yarn.server.resourcemanager.ResourceManager$ApplicationEventDispatcher
2018-02-23 19:25:05,679 INFO org.apache.hadoop.yarn.event.AsyncDispatcher: Registering class org.apache.hadoop.yarn.server.resourcemanager.rmapp.attempt.RMAppAttemptEventType for class org.apache.hadoop.yarn.server.resourcemanager.ResourceManager$ApplicationAttemptEventDispatcher
2018-02-23 19:25:05,679 INFO org.apache.hadoop.yarn.event.AsyncDispatcher: Registering class org.apache.hadoop.yarn.server.resourcemanager.rmnode.RMNodeEventType for class org.apache.hadoop.yarn.server.resourcemanager.ResourceManager$NodeEventDispatcher
2018-02-23 19:25:05,719 INFO org.apache.hadoop.metrics2.impl.MetricsConfig: loaded properties from hadoop-metrics2.properties
2018-02-23 19:25:05,754 INFO org.apache.hadoop.metrics2.impl.MetricsSystemImpl: Scheduled snapshot period at 10 second(s).
2018-02-23 19:25:05,754 INFO org.apache.hadoop.metrics2.impl.MetricsSystemImpl: ResourceManager metrics system started
2018-02-23 19:25:05,761 INFO org.apache.hadoop.yarn.event.AsyncDispatcher: Registering class org.apache.hadoop.yarn.server.resourcemanager.RMAppManagerEventType for class org.apache.hadoop.yarn.server.resourcemanager.RMAppManager
2018-02-23 19:25:05,765 INFO org.apache.hadoop.yarn.event.AsyncDispatcher: Registering class org.apache.hadoop.yarn.server.resourcemanager.amlauncher.AMLauncherEventType for class org.apache.hadoop.yarn.server.resourcemanager.amlauncher.ApplicationMasterLauncher
2018-02-23 19:25:05,766 INFO org.apache.hadoop.yarn.server.resourcemanager.RMNMInfo: Registered RMNMInfo MBean
2018-02-23 19:25:05,767 INFO org.apache.hadoop.yarn.security.YarnAuthorizationProvider: org.apache.hadoop.yarn.security.ConfiguredYarnAuthorizer is instiantiated.
2018-02-23 19:25:05,768 INFO org.apache.hadoop.util.HostsFileReader: Refreshing hosts (include/exclude) list
2018-02-23 19:25:05,770 INFO org.apache.hadoop.conf.Configuration: found resource capacity-scheduler.xml at file:/opt/hadoop-2.7.2/etc/hadoop/capacity-scheduler.xml
2018-02-23 19:25:05,794 INFO org.apache.hadoop.yarn.server.resourcemanager.scheduler.capacity.CapacitySchedulerConfiguration: max alloc mb per queue for root is undefined
2018-02-23 19:25:05,794 INFO org.apache.hadoop.yarn.server.resourcemanager.scheduler.capacity.CapacitySchedulerConfiguration: max alloc vcore per queue for root is undefined
2018-02-23 19:25:05,796 INFO org.apache.hadoop.yarn.server.resourcemanager.scheduler.capacity.ParentQueue: root, capacity=1.0, asboluteCapacity=1.0, maxCapacity=1.0, asboluteMaxCapacity=1.0, state=RUNNING, acls=SUBMIT_APP:*ADMINISTER_QUEUE:*, labels=*,
, reservationsContinueLooking=true
2018-02-23 19:25:05,796 INFO org.apache.hadoop.yarn.server.resourcemanager.scheduler.capacity.ParentQueue: Initialized parent-queue root name=root, fullname=root
2018-02-23 19:25:05,800 INFO org.apache.hadoop.yarn.server.resourcemanager.scheduler.capacity.CapacitySchedulerConfiguration: max alloc mb per queue for root.default is undefined
2018-02-23 19:25:05,800 INFO org.apache.hadoop.yarn.server.resourcemanager.scheduler.capacity.CapacitySchedulerConfiguration: max alloc vcore per queue for root.default is undefined
2018-02-23 19:25:05,801 INFO org.apache.hadoop.yarn.server.resourcemanager.scheduler.capacity.LeafQueue: Initializing default
capacity = 1.0 [= (float) configuredCapacity / 100 ]
asboluteCapacity = 1.0 [= parentAbsoluteCapacity * capacity ]
maxCapacity = 1.0 [= configuredMaxCapacity ]
absoluteMaxCapacity = 1.0 [= 1.0 maximumCapacity undefined, (parentAbsoluteMaxCapacity * maximumCapacity) / 100 otherwise ]
userLimit = 100 [= configuredUserLimit ]
userLimitFactor = 1.0 [= configuredUserLimitFactor ]
maxApplications = 10000 [= configuredMaximumSystemApplicationsPerQueue or (int)(configuredMaximumSystemApplications * absoluteCapacity)]
maxApplicationsPerUser = 10000 [= (int)(maxApplications * (userLimit / 100.0f) * userLimitFactor) ]
usedCapacity = 0.0 [= usedResourcesMemory / (clusterResourceMemory * absoluteCapacity)]
absoluteUsedCapacity = 0.0 [= usedResourcesMemory / clusterResourceMemory]
maxAMResourcePerQueuePercent = 0.1 [= configuredMaximumAMResourcePercent ]
minimumAllocationFactor = 0.875 [= (float)(maximumAllocationMemory - minimumAllocationMemory) / maximumAllocationMemory ]
maximumAllocation = <memory:8192, vCores:32> [= configuredMaxAllocation ]
numContainers = 0 [= currentNumContainers ]
state = RUNNING [= configuredState ]
acls = SUBMIT_APP:*ADMINISTER_QUEUE:* [= configuredAcls ]
nodeLocalityDelay = 40
labels=*,
nodeLocalityDelay = 40
reservationsContinueLooking = true
preemptionDisabled = true

2018-02-23 19:25:05,801 INFO org.apache.hadoop.yarn.server.resourcemanager.scheduler.capacity.CapacityScheduler: Initialized queue: default: capacity=1.0, absoluteCapacity=1.0, usedResources=<memory:0, vCores:0>, usedCapacity=0.0, absoluteUsedCapacity=0.0, numApps=0, numContainers=0
2018-02-23 19:25:05,801 INFO org.apache.hadoop.yarn.server.resourcemanager.scheduler.capacity.CapacityScheduler: Initialized queue: root: numChildQueue= 1, capacity=1.0, absoluteCapacity=1.0, usedResources=<memory:0, vCores:0>usedCapacity=0.0, numApps=0, numContainers=0
2018-02-23 19:25:05,802 INFO org.apache.hadoop.yarn.server.resourcemanager.scheduler.capacity.CapacityScheduler: Initialized root queue root: numChildQueue= 1, capacity=1.0, absoluteCapacity=1.0, usedResources=<memory:0, vCores:0>usedCapacity=0.0, numApps=0, numContainers=0
2018-02-23 19:25:05,802 INFO org.apache.hadoop.yarn.server.resourcemanager.scheduler.capacity.CapacityScheduler: Initialized queue mappings, override: false
2018-02-23 19:25:05,802 INFO org.apache.hadoop.yarn.server.resourcemanager.scheduler.capacity.CapacityScheduler: Initialized CapacityScheduler with calculator=class org.apache.hadoop.yarn.util.resource.DefaultResourceCalculator, minimumAllocation=<<memory:1024, vCores:1>>, maximumAllocation=<<memory:8192, vCores:32>>, asynchronousScheduling=false, asyncScheduleInterval=5ms
2018-02-23 19:25:05,809 INFO org.apache.hadoop.yarn.server.resourcemanager.metrics.SystemMetricsPublisher: YARN system metrics publishing service is not enabled
2018-02-23 19:25:05,809 INFO org.apache.hadoop.yarn.server.resourcemanager.ResourceManager: Transitioning to active state
2018-02-23 19:25:05,815 INFO org.apache.hadoop.yarn.server.resourcemanager.recovery.RMStateStore: Updating AMRMToken
2018-02-23 19:25:05,815 INFO org.apache.hadoop.yarn.server.resourcemanager.security.RMContainerTokenSecretManager: Rolling master-key for container-tokens
2018-02-23 19:25:05,815 INFO org.apache.hadoop.yarn.server.resourcemanager.security.NMTokenSecretManagerInRM: Rolling master-key for nm-tokens
2018-02-23 19:25:05,815 INFO org.apache.hadoop.security.token.delegation.AbstractDelegationTokenSecretManager: Updating the current master key for generating delegation tokens
2018-02-23 19:25:05,816 INFO org.apache.hadoop.yarn.server.resourcemanager.security.RMDelegationTokenSecretManager: storing master key with keyID 1
2018-02-23 19:25:05,816 INFO org.apache.hadoop.yarn.server.resourcemanager.recovery.RMStateStore: Storing RMDTMasterKey.
2018-02-23 19:25:05,823 INFO org.apache.hadoop.security.token.delegation.AbstractDelegationTokenSecretManager: Starting expired delegation token remover thread, tokenRemoverScanInterval=60 min(s)
2018-02-23 19:25:05,823 INFO org.apache.hadoop.security.token.delegation.AbstractDelegationTokenSecretManager: Updating the current master key for generating delegation tokens
2018-02-23 19:25:05,823 INFO org.apache.hadoop.yarn.server.resourcemanager.security.RMDelegationTokenSecretManager: storing master key with keyID 2
2018-02-23 19:25:05,823 INFO org.apache.hadoop.yarn.server.resourcemanager.recovery.RMStateStore: Storing RMDTMasterKey.
2018-02-23 19:25:05,824 INFO org.apache.hadoop.yarn.event.AsyncDispatcher: Registering class org.apache.hadoop.yarn.nodelabels.event.NodeLabelsStoreEventType for class org.apache.hadoop.yarn.nodelabels.CommonNodeLabelsManager$ForwardingEventHandler
2018-02-23 19:25:05,849 INFO org.apache.hadoop.ipc.CallQueueManager: Using callQueue class java.util.concurrent.LinkedBlockingQueue
2018-02-23 19:25:05,856 INFO org.apache.hadoop.ipc.Server: Starting Socket Reader #1 for port 8031
2018-02-23 19:25:05,864 INFO org.apache.hadoop.yarn.factories.impl.pb.RpcServerFactoryPBImpl: Adding protocol org.apache.hadoop.yarn.server.api.ResourceTrackerPB to the server
2018-02-23 19:25:05,864 INFO org.apache.hadoop.ipc.Server: IPC Server Responder: starting
2018-02-23 19:25:05,864 INFO org.apache.hadoop.ipc.Server: IPC Server listener on 8031: starting
2018-02-23 19:25:05,884 INFO org.apache.hadoop.ipc.CallQueueManager: Using callQueue class java.util.concurrent.LinkedBlockingQueue
2018-02-23 19:25:05,890 INFO org.apache.hadoop.ipc.Server: Starting Socket Reader #1 for port 8030
2018-02-23 19:25:05,897 INFO org.apache.hadoop.yarn.factories.impl.pb.RpcServerFactoryPBImpl: Adding protocol org.apache.hadoop.yarn.api.ApplicationMasterProtocolPB to the server
2018-02-23 19:25:05,898 INFO org.apache.hadoop.ipc.Server: IPC Server Responder: starting
2018-02-23 19:25:05,898 INFO org.apache.hadoop.ipc.Server: IPC Server listener on 8030: starting
2018-02-23 19:25:05,970 INFO org.apache.hadoop.ipc.CallQueueManager: Using callQueue class java.util.concurrent.LinkedBlockingQueue
2018-02-23 19:25:05,970 INFO org.apache.hadoop.ipc.Server: Starting Socket Reader #1 for port 8032
2018-02-23 19:25:05,972 INFO org.apache.hadoop.yarn.factories.impl.pb.RpcServerFactoryPBImpl: Adding protocol org.apache.hadoop.yarn.api.ApplicationClientProtocolPB to the server
2018-02-23 19:25:05,972 INFO org.apache.hadoop.ipc.Server: IPC Server Responder: starting
2018-02-23 19:25:05,972 INFO org.apache.hadoop.ipc.Server: IPC Server listener on 8032: starting
2018-02-23 19:25:05,976 INFO org.apache.hadoop.yarn.server.resourcemanager.ResourceManager: Transitioned to active state
2018-02-23 19:25:06,025 INFO org.mortbay.log: Logging to org.slf4j.impl.Log4jLoggerAdapter(org.mortbay.log) via org.mortbay.log.Slf4jLog
2018-02-23 19:25:06,030 INFO org.apache.hadoop.security.authentication.server.AuthenticationFilter: Unable to initialize FileSignerSecretProvider, falling back to use random secrets.
2018-02-23 19:25:06,034 INFO org.apache.hadoop.http.HttpRequestLog: Http request log for http.requests.resourcemanager is not defined
2018-02-23 19:25:06,039 INFO org.apache.hadoop.http.HttpServer2: Added global filter 'safety' (class=org.apache.hadoop.http.HttpServer2$QuotingInputFilter)
2018-02-23 19:25:06,041 INFO org.apache.hadoop.http.HttpServer2: Added filter RMAuthenticationFilter (class=org.apache.hadoop.yarn.server.security.http.RMAuthenticationFilter) to context cluster
2018-02-23 19:25:06,041 INFO org.apache.hadoop.http.HttpServer2: Added filter RMAuthenticationFilter (class=org.apache.hadoop.yarn.server.security.http.RMAuthenticationFilter) to context static
2018-02-23 19:25:06,041 INFO org.apache.hadoop.http.HttpServer2: Added filter RMAuthenticationFilter (class=org.apache.hadoop.yarn.server.security.http.RMAuthenticationFilter) to context logs
2018-02-23 19:25:06,042 INFO org.apache.hadoop.http.HttpServer2: Added filter static_user_filter (class=org.apache.hadoop.http.lib.StaticUserWebFilter$StaticUserFilter) to context cluster
2018-02-23 19:25:06,042 INFO org.apache.hadoop.http.HttpServer2: Added filter static_user_filter (class=org.apache.hadoop.http.lib.StaticUserWebFilter$StaticUserFilter) to context static
2018-02-23 19:25:06,042 INFO org.apache.hadoop.http.HttpServer2: Added filter static_user_filter (class=org.apache.hadoop.http.lib.StaticUserWebFilter$StaticUserFilter) to context logs
2018-02-23 19:25:06,044 INFO org.apache.hadoop.http.HttpServer2: adding path spec: /cluster/*
2018-02-23 19:25:06,044 INFO org.apache.hadoop.http.HttpServer2: adding path spec: /ws/*
2018-02-23 19:25:06,298 INFO org.apache.hadoop.yarn.webapp.WebApps: Registered webapp guice modules
2018-02-23 19:25:06,300 INFO org.apache.hadoop.http.HttpServer2: Jetty bound to port 8088
2018-02-23 19:25:06,300 INFO org.mortbay.log: jetty-6.1.26
2018-02-23 19:25:06,344 INFO org.mortbay.log: Extract jar:file:/opt/hadoop-2.7.2/share/hadoop/yarn/hadoop-yarn-common-2.7.2.jar!/webapps/cluster to /tmp/Jetty_0_0_0_0_8088_cluster____u0rgz3/webapp
2018-02-23 19:25:06,474 INFO org.apache.hadoop.security.token.delegation.AbstractDelegationTokenSecretManager: Updating the current master key for generating delegation tokens
2018-02-23 19:25:06,474 INFO org.apache.hadoop.security.token.delegation.AbstractDelegationTokenSecretManager: Starting expired delegation token remover thread, tokenRemoverScanInterval=60 min(s)
2018-02-23 19:25:06,474 INFO org.apache.hadoop.security.token.delegation.AbstractDelegationTokenSecretManager: Updating the current master key for generating delegation tokens
2018-02-23 19:25:07,112 INFO org.mortbay.log: Started HttpServer2$SelectChannelConnectorWithSafeStartup@0.0.0.0:8088
2018-02-23 19:25:07,112 INFO org.apache.hadoop.yarn.webapp.WebApps: Web app cluster started at 8088
2018-02-23 19:25:07,145 INFO org.apache.hadoop.ipc.CallQueueManager: Using callQueue class java.util.concurrent.LinkedBlockingQueue
2018-02-23 19:25:07,145 INFO org.apache.hadoop.ipc.Server: Starting Socket Reader #1 for port 8033
2018-02-23 19:25:07,146 INFO org.apache.hadoop.yarn.factories.impl.pb.RpcServerFactoryPBImpl: Adding protocol org.apache.hadoop.yarn.server.api.ResourceManagerAdministrationProtocolPB to the server
2018-02-23 19:25:07,146 INFO org.apache.hadoop.ipc.Server: IPC Server Responder: starting
2018-02-23 19:25:07,146 INFO org.apache.hadoop.ipc.Server: IPC Server listener on 8033: starting
2018-02-23 19:25:08,245 INFO org.apache.hadoop.yarn.util.RackResolver: Resolved ustc-OptiPlex-7050 to /default-rack
2018-02-23 19:25:08,247 INFO org.apache.hadoop.yarn.server.resourcemanager.ResourceTrackerService: NodeManager from node ustc-OptiPlex-7050(cmPort: 46541 httpPort: 8042) registered with capability: <memory:8192, vCores:8>, assigned nodeId ustc-OptiPlex-7050:46541
2018-02-23 19:25:08,248 INFO org.apache.hadoop.yarn.server.resourcemanager.rmnode.RMNodeImpl: ustc-OptiPlex-7050:46541 Node Transitioned from NEW to RUNNING
2018-02-23 19:25:08,251 INFO org.apache.hadoop.yarn.server.resourcemanager.scheduler.capacity.CapacityScheduler: Added node ustc-OptiPlex-7050:46541 clusterResource: <memory:8192, vCores:8>
2018-02-23 19:35:05,771 INFO org.apache.hadoop.yarn.server.resourcemanager.scheduler.AbstractYarnScheduler: Release request cache is cleaned up
2018-02-23 19:39:02,808 INFO org.apache.hadoop.yarn.server.resourcemanager.ClientRMService: Allocated new applicationId: 1
2018-02-23 19:39:03,561 INFO org.apache.hadoop.yarn.server.resourcemanager.ClientRMService: Application with id 1 submitted by user root
2018-02-23 19:39:03,561 INFO org.apache.hadoop.yarn.server.resourcemanager.rmapp.RMAppImpl: Storing application with id application_1519385105809_0001
2018-02-23 19:39:03,561 INFO org.apache.hadoop.yarn.server.resourcemanager.RMAuditLogger: USER=root	IP=127.0.0.1	OPERATION=Submit Application Request	TARGET=ClientRMService	RESULT=SUCCESS	APPID=application_1519385105809_0001
2018-02-23 19:39:03,565 INFO org.apache.hadoop.yarn.server.resourcemanager.rmapp.RMAppImpl: application_1519385105809_0001 State change from NEW to NEW_SAVING
2018-02-23 19:39:03,565 INFO org.apache.hadoop.yarn.server.resourcemanager.recovery.RMStateStore: Storing info for app: application_1519385105809_0001
2018-02-23 19:39:03,566 INFO org.apache.hadoop.yarn.server.resourcemanager.rmapp.RMAppImpl: application_1519385105809_0001 State change from NEW_SAVING to SUBMITTED
2018-02-23 19:39:03,566 INFO org.apache.hadoop.yarn.server.resourcemanager.scheduler.capacity.ParentQueue: Application added - appId: application_1519385105809_0001 user: root leaf-queue of parent: root #applications: 1
2018-02-23 19:39:03,567 INFO org.apache.hadoop.yarn.server.resourcemanager.scheduler.capacity.CapacityScheduler: Accepted application application_1519385105809_0001 from user: root, in queue: default
2018-02-23 19:39:03,571 INFO org.apache.hadoop.yarn.server.resourcemanager.rmapp.RMAppImpl: application_1519385105809_0001 State change from SUBMITTED to ACCEPTED
2018-02-23 19:39:03,584 INFO org.apache.hadoop.yarn.server.resourcemanager.ApplicationMasterService: Registering app attempt : appattempt_1519385105809_0001_000001
2018-02-23 19:39:03,585 INFO org.apache.hadoop.yarn.server.resourcemanager.rmapp.attempt.RMAppAttemptImpl: appattempt_1519385105809_0001_000001 State change from NEW to SUBMITTED
2018-02-23 19:39:03,593 WARN org.apache.hadoop.yarn.server.resourcemanager.scheduler.capacity.LeafQueue: maximum-am-resource-percent is insufficient to start a single application in queue, it is likely set too low. skipping enforcement to allow at least one application to start
2018-02-23 19:39:03,593 WARN org.apache.hadoop.yarn.server.resourcemanager.scheduler.capacity.LeafQueue: maximum-am-resource-percent is insufficient to start a single application in queue for user, it is likely set too low. skipping enforcement to allow at least one application to start
2018-02-23 19:39:03,593 INFO org.apache.hadoop.yarn.server.resourcemanager.scheduler.capacity.LeafQueue: Application application_1519385105809_0001 from user: root activated in queue: default
2018-02-23 19:39:03,593 INFO org.apache.hadoop.yarn.server.resourcemanager.scheduler.capacity.LeafQueue: Application added - appId: application_1519385105809_0001 user: org.apache.hadoop.yarn.server.resourcemanager.scheduler.capacity.LeafQueue$User@78608d72, leaf-queue: default #user-pending-applications: 0 #user-active-applications: 1 #queue-pending-applications: 0 #queue-active-applications: 1
2018-02-23 19:39:03,594 INFO org.apache.hadoop.yarn.server.resourcemanager.scheduler.capacity.CapacityScheduler: Added Application Attempt appattempt_1519385105809_0001_000001 to scheduler from user root in queue default
2018-02-23 19:39:03,595 INFO org.apache.hadoop.yarn.server.resourcemanager.rmapp.attempt.RMAppAttemptImpl: appattempt_1519385105809_0001_000001 State change from SUBMITTED to SCHEDULED
2018-02-23 19:39:03,635 INFO org.apache.hadoop.yarn.server.resourcemanager.rmcontainer.RMContainerImpl: container_1519385105809_0001_01_000001 Container Transitioned from NEW to ALLOCATED
2018-02-23 19:39:03,635 INFO org.apache.hadoop.yarn.server.resourcemanager.RMAuditLogger: USER=root	OPERATION=AM Allocated Container	TARGET=SchedulerApp	RESULT=SUCCESS	APPID=application_1519385105809_0001	CONTAINERID=container_1519385105809_0001_01_000001
2018-02-23 19:39:03,636 INFO org.apache.hadoop.yarn.server.resourcemanager.scheduler.SchedulerNode: Assigned container container_1519385105809_0001_01_000001 of capacity <memory:2048, vCores:1> on host ustc-OptiPlex-7050:46541, which has 1 containers, <memory:2048, vCores:1> used and <memory:6144, vCores:7> available after allocation
2018-02-23 19:39:03,636 INFO org.apache.hadoop.yarn.server.resourcemanager.scheduler.capacity.LeafQueue: assignedContainer application attempt=appattempt_1519385105809_0001_000001 container=Container: [ContainerId: container_1519385105809_0001_01_000001, NodeId: ustc-OptiPlex-7050:46541, NodeHttpAddress: ustc-OptiPlex-7050:8042, Resource: <memory:2048, vCores:1>, Priority: 0, Token: null, ] queue=default: capacity=1.0, absoluteCapacity=1.0, usedResources=<memory:0, vCores:0>, usedCapacity=0.0, absoluteUsedCapacity=0.0, numApps=1, numContainers=0 clusterResource=<memory:8192, vCores:8>
2018-02-23 19:39:03,636 INFO org.apache.hadoop.yarn.server.resourcemanager.scheduler.capacity.ParentQueue: Re-sorting assigned queue: root.default stats: default: capacity=1.0, absoluteCapacity=1.0, usedResources=<memory:2048, vCores:1>, usedCapacity=0.25, absoluteUsedCapacity=0.25, numApps=1, numContainers=1
2018-02-23 19:39:03,636 INFO org.apache.hadoop.yarn.server.resourcemanager.scheduler.capacity.ParentQueue: assignedContainer queue=root usedCapacity=0.25 absoluteUsedCapacity=0.25 used=<memory:2048, vCores:1> cluster=<memory:8192, vCores:8>
2018-02-23 19:39:03,645 INFO org.apache.hadoop.yarn.server.resourcemanager.security.NMTokenSecretManagerInRM: Sending NMToken for nodeId : ustc-OptiPlex-7050:46541 for container : container_1519385105809_0001_01_000001
2018-02-23 19:39:03,649 INFO org.apache.hadoop.yarn.server.resourcemanager.rmcontainer.RMContainerImpl: container_1519385105809_0001_01_000001 Container Transitioned from ALLOCATED to ACQUIRED
2018-02-23 19:39:03,650 INFO org.apache.hadoop.yarn.server.resourcemanager.security.NMTokenSecretManagerInRM: Clear node set for appattempt_1519385105809_0001_000001
2018-02-23 19:39:03,651 INFO org.apache.hadoop.yarn.server.resourcemanager.rmapp.attempt.RMAppAttemptImpl: Storing attempt: AppId: application_1519385105809_0001 AttemptId: appattempt_1519385105809_0001_000001 MasterContainer: Container: [ContainerId: container_1519385105809_0001_01_000001, NodeId: ustc-OptiPlex-7050:46541, NodeHttpAddress: ustc-OptiPlex-7050:8042, Resource: <memory:2048, vCores:1>, Priority: 0, Token: Token { kind: ContainerToken, service: 127.0.1.1:46541 }, ]
2018-02-23 19:39:03,658 INFO org.apache.hadoop.yarn.server.resourcemanager.rmapp.attempt.RMAppAttemptImpl: appattempt_1519385105809_0001_000001 State change from SCHEDULED to ALLOCATED_SAVING
2018-02-23 19:39:03,659 INFO org.apache.hadoop.yarn.server.resourcemanager.rmapp.attempt.RMAppAttemptImpl: appattempt_1519385105809_0001_000001 State change from ALLOCATED_SAVING to ALLOCATED
2018-02-23 19:39:03,660 INFO org.apache.hadoop.yarn.server.resourcemanager.amlauncher.AMLauncher: Launching masterappattempt_1519385105809_0001_000001
2018-02-23 19:39:03,678 INFO org.apache.hadoop.yarn.server.resourcemanager.amlauncher.AMLauncher: Setting up container Container: [ContainerId: container_1519385105809_0001_01_000001, NodeId: ustc-OptiPlex-7050:46541, NodeHttpAddress: ustc-OptiPlex-7050:8042, Resource: <memory:2048, vCores:1>, Priority: 0, Token: Token { kind: ContainerToken, service: 127.0.1.1:46541 }, ] for AM appattempt_1519385105809_0001_000001
2018-02-23 19:39:03,678 INFO org.apache.hadoop.yarn.server.resourcemanager.amlauncher.AMLauncher: Command to launch container container_1519385105809_0001_01_000001 : $JAVA_HOME/bin/java -Djava.io.tmpdir=$PWD/tmp -Dlog4j.configuration=container-log4j.properties -Dyarn.app.container.log.dir=<LOG_DIR> -Dyarn.app.container.log.filesize=0 -Dhadoop.root.logger=INFO,CLA -Dhadoop.root.logfile=syslog  -Xmx1024m org.apache.hadoop.mapreduce.v2.app.MRAppMaster 1><LOG_DIR>/stdout 2><LOG_DIR>/stderr 
2018-02-23 19:39:03,679 INFO org.apache.hadoop.yarn.server.resourcemanager.security.AMRMTokenSecretManager: Create AMRMToken for ApplicationAttempt: appattempt_1519385105809_0001_000001
2018-02-23 19:39:03,681 INFO org.apache.hadoop.yarn.server.resourcemanager.security.AMRMTokenSecretManager: Creating password for appattempt_1519385105809_0001_000001
2018-02-23 19:39:03,835 INFO org.apache.hadoop.yarn.server.resourcemanager.amlauncher.AMLauncher: Done launching container Container: [ContainerId: container_1519385105809_0001_01_000001, NodeId: ustc-OptiPlex-7050:46541, NodeHttpAddress: ustc-OptiPlex-7050:8042, Resource: <memory:2048, vCores:1>, Priority: 0, Token: Token { kind: ContainerToken, service: 127.0.1.1:46541 }, ] for AM appattempt_1519385105809_0001_000001
2018-02-23 19:39:03,835 INFO org.apache.hadoop.yarn.server.resourcemanager.rmapp.attempt.RMAppAttemptImpl: appattempt_1519385105809_0001_000001 State change from ALLOCATED to LAUNCHED
2018-02-23 19:39:04,584 INFO org.apache.hadoop.yarn.server.resourcemanager.rmcontainer.RMContainerImpl: container_1519385105809_0001_01_000001 Container Transitioned from ACQUIRED to RUNNING
2018-02-23 19:39:06,773 INFO SecurityLogger.org.apache.hadoop.ipc.Server: Auth successful for appattempt_1519385105809_0001_000001 (auth:SIMPLE)
2018-02-23 19:39:06,778 INFO org.apache.hadoop.yarn.server.resourcemanager.ApplicationMasterService: AM registration appattempt_1519385105809_0001_000001
2018-02-23 19:39:06,778 INFO org.apache.hadoop.yarn.server.resourcemanager.RMAuditLogger: USER=root	IP=127.0.0.1	OPERATION=Register App Master	TARGET=ApplicationMasterService	RESULT=SUCCESS	APPID=application_1519385105809_0001	APPATTEMPTID=appattempt_1519385105809_0001_000001
2018-02-23 19:39:06,778 INFO org.apache.hadoop.yarn.server.resourcemanager.rmapp.attempt.RMAppAttemptImpl: appattempt_1519385105809_0001_000001 State change from LAUNCHED to RUNNING
2018-02-23 19:39:06,778 INFO org.apache.hadoop.yarn.server.resourcemanager.rmapp.RMAppImpl: application_1519385105809_0001 State change from ACCEPTED to RUNNING
2018-02-23 19:39:08,590 INFO org.apache.hadoop.yarn.server.resourcemanager.rmcontainer.RMContainerImpl: container_1519385105809_0001_01_000002 Container Transitioned from NEW to ALLOCATED
2018-02-23 19:39:08,590 INFO org.apache.hadoop.yarn.server.resourcemanager.RMAuditLogger: USER=root	OPERATION=AM Allocated Container	TARGET=SchedulerApp	RESULT=SUCCESS	APPID=application_1519385105809_0001	CONTAINERID=container_1519385105809_0001_01_000002
2018-02-23 19:39:08,590 INFO org.apache.hadoop.yarn.server.resourcemanager.scheduler.SchedulerNode: Assigned container container_1519385105809_0001_01_000002 of capacity <memory:1024, vCores:1> on host ustc-OptiPlex-7050:46541, which has 2 containers, <memory:3072, vCores:2> used and <memory:5120, vCores:6> available after allocation
2018-02-23 19:39:08,590 INFO org.apache.hadoop.yarn.server.resourcemanager.scheduler.capacity.LeafQueue: assignedContainer application attempt=appattempt_1519385105809_0001_000001 container=Container: [ContainerId: container_1519385105809_0001_01_000002, NodeId: ustc-OptiPlex-7050:46541, NodeHttpAddress: ustc-OptiPlex-7050:8042, Resource: <memory:1024, vCores:1>, Priority: 20, Token: null, ] queue=default: capacity=1.0, absoluteCapacity=1.0, usedResources=<memory:2048, vCores:1>, usedCapacity=0.25, absoluteUsedCapacity=0.25, numApps=1, numContainers=1 clusterResource=<memory:8192, vCores:8>
2018-02-23 19:39:08,590 INFO org.apache.hadoop.yarn.server.resourcemanager.scheduler.capacity.ParentQueue: Re-sorting assigned queue: root.default stats: default: capacity=1.0, absoluteCapacity=1.0, usedResources=<memory:3072, vCores:2>, usedCapacity=0.375, absoluteUsedCapacity=0.375, numApps=1, numContainers=2
2018-02-23 19:39:08,591 INFO org.apache.hadoop.yarn.server.resourcemanager.scheduler.capacity.ParentQueue: assignedContainer queue=root usedCapacity=0.375 absoluteUsedCapacity=0.375 used=<memory:3072, vCores:2> cluster=<memory:8192, vCores:8>
2018-02-23 19:39:08,849 INFO org.apache.hadoop.yarn.server.resourcemanager.security.NMTokenSecretManagerInRM: Sending NMToken for nodeId : ustc-OptiPlex-7050:46541 for container : container_1519385105809_0001_01_000002
2018-02-23 19:39:08,851 INFO org.apache.hadoop.yarn.server.resourcemanager.rmcontainer.RMContainerImpl: container_1519385105809_0001_01_000002 Container Transitioned from ALLOCATED to ACQUIRED
2018-02-23 19:39:09,590 INFO org.apache.hadoop.yarn.server.resourcemanager.rmcontainer.RMContainerImpl: container_1519385105809_0001_01_000002 Container Transitioned from ACQUIRED to RUNNING
2018-02-23 19:39:09,872 INFO org.apache.hadoop.yarn.server.resourcemanager.scheduler.AppSchedulingInfo: checking for deactivate of application :application_1519385105809_0001
2018-02-23 19:39:11,389 INFO org.apache.hadoop.yarn.server.resourcemanager.rmcontainer.RMContainerImpl: container_1519385105809_0001_01_000002 Container Transitioned from RUNNING to COMPLETED
2018-02-23 19:39:11,390 INFO org.apache.hadoop.yarn.server.resourcemanager.scheduler.common.fica.FiCaSchedulerApp: Completed container: container_1519385105809_0001_01_000002 in state: COMPLETED event:FINISHED
2018-02-23 19:39:11,390 INFO org.apache.hadoop.yarn.server.resourcemanager.RMAuditLogger: USER=root	OPERATION=AM Released Container	TARGET=SchedulerApp	RESULT=SUCCESS	APPID=application_1519385105809_0001	CONTAINERID=container_1519385105809_0001_01_000002
2018-02-23 19:39:11,390 INFO org.apache.hadoop.yarn.server.resourcemanager.scheduler.SchedulerNode: Released container container_1519385105809_0001_01_000002 of capacity <memory:1024, vCores:1> on host ustc-OptiPlex-7050:46541, which currently has 1 containers, <memory:2048, vCores:1> used and <memory:6144, vCores:7> available, release resources=true
2018-02-23 19:39:11,390 INFO org.apache.hadoop.yarn.server.resourcemanager.scheduler.capacity.LeafQueue: default used=<memory:2048, vCores:1> numContainers=1 user=root user-resources=<memory:2048, vCores:1>
2018-02-23 19:39:11,391 INFO org.apache.hadoop.yarn.server.resourcemanager.scheduler.capacity.LeafQueue: completedContainer container=Container: [ContainerId: container_1519385105809_0001_01_000002, NodeId: ustc-OptiPlex-7050:46541, NodeHttpAddress: ustc-OptiPlex-7050:8042, Resource: <memory:1024, vCores:1>, Priority: 20, Token: Token { kind: ContainerToken, service: 127.0.1.1:46541 }, ] queue=default: capacity=1.0, absoluteCapacity=1.0, usedResources=<memory:2048, vCores:1>, usedCapacity=0.25, absoluteUsedCapacity=0.25, numApps=1, numContainers=1 cluster=<memory:8192, vCores:8>
2018-02-23 19:39:11,391 INFO org.apache.hadoop.yarn.server.resourcemanager.scheduler.capacity.ParentQueue: completedContainer queue=root usedCapacity=0.25 absoluteUsedCapacity=0.25 used=<memory:2048, vCores:1> cluster=<memory:8192, vCores:8>
2018-02-23 19:39:11,392 INFO org.apache.hadoop.yarn.server.resourcemanager.scheduler.capacity.ParentQueue: Re-sorting completed queue: root.default stats: default: capacity=1.0, absoluteCapacity=1.0, usedResources=<memory:2048, vCores:1>, usedCapacity=0.25, absoluteUsedCapacity=0.25, numApps=1, numContainers=1
2018-02-23 19:39:11,392 INFO org.apache.hadoop.yarn.server.resourcemanager.scheduler.capacity.CapacityScheduler: Application attempt appattempt_1519385105809_0001_000001 released container container_1519385105809_0001_01_000002 on node: host: ustc-OptiPlex-7050:46541 #containers=1 available=<memory:6144, vCores:7> used=<memory:2048, vCores:1> with event: FINISHED
2018-02-23 19:39:12,391 INFO org.apache.hadoop.yarn.server.resourcemanager.rmcontainer.RMContainerImpl: container_1519385105809_0001_01_000003 Container Transitioned from NEW to ALLOCATED
2018-02-23 19:39:12,391 INFO org.apache.hadoop.yarn.server.resourcemanager.RMAuditLogger: USER=root	OPERATION=AM Allocated Container	TARGET=SchedulerApp	RESULT=SUCCESS	APPID=application_1519385105809_0001	CONTAINERID=container_1519385105809_0001_01_000003
2018-02-23 19:39:12,391 INFO org.apache.hadoop.yarn.server.resourcemanager.scheduler.SchedulerNode: Assigned container container_1519385105809_0001_01_000003 of capacity <memory:1024, vCores:1> on host ustc-OptiPlex-7050:46541, which has 2 containers, <memory:3072, vCores:2> used and <memory:5120, vCores:6> available after allocation
2018-02-23 19:39:12,391 INFO org.apache.hadoop.yarn.server.resourcemanager.scheduler.capacity.LeafQueue: assignedContainer application attempt=appattempt_1519385105809_0001_000001 container=Container: [ContainerId: container_1519385105809_0001_01_000003, NodeId: ustc-OptiPlex-7050:46541, NodeHttpAddress: ustc-OptiPlex-7050:8042, Resource: <memory:1024, vCores:1>, Priority: 10, Token: null, ] queue=default: capacity=1.0, absoluteCapacity=1.0, usedResources=<memory:2048, vCores:1>, usedCapacity=0.25, absoluteUsedCapacity=0.25, numApps=1, numContainers=1 clusterResource=<memory:8192, vCores:8>
2018-02-23 19:39:12,391 INFO org.apache.hadoop.yarn.server.resourcemanager.scheduler.capacity.ParentQueue: Re-sorting assigned queue: root.default stats: default: capacity=1.0, absoluteCapacity=1.0, usedResources=<memory:3072, vCores:2>, usedCapacity=0.375, absoluteUsedCapacity=0.375, numApps=1, numContainers=2
2018-02-23 19:39:12,391 INFO org.apache.hadoop.yarn.server.resourcemanager.scheduler.capacity.ParentQueue: assignedContainer queue=root usedCapacity=0.375 absoluteUsedCapacity=0.375 used=<memory:3072, vCores:2> cluster=<memory:8192, vCores:8>
2018-02-23 19:39:12,890 INFO org.apache.hadoop.yarn.server.resourcemanager.rmcontainer.RMContainerImpl: container_1519385105809_0001_01_000003 Container Transitioned from ALLOCATED to ACQUIRED
2018-02-23 19:39:13,391 INFO org.apache.hadoop.yarn.server.resourcemanager.rmcontainer.RMContainerImpl: container_1519385105809_0001_01_000003 Container Transitioned from ACQUIRED to RUNNING
2018-02-23 19:39:13,894 INFO org.apache.hadoop.yarn.server.resourcemanager.scheduler.AppSchedulingInfo: checking for deactivate of application :application_1519385105809_0001
2018-02-23 19:39:14,787 INFO org.apache.hadoop.yarn.server.resourcemanager.rmapp.attempt.RMAppAttemptImpl: Updating application attempt appattempt_1519385105809_0001_000001 with final state: FINISHING, and exit status: -1000
2018-02-23 19:39:14,787 INFO org.apache.hadoop.yarn.server.resourcemanager.rmapp.attempt.RMAppAttemptImpl: appattempt_1519385105809_0001_000001 State change from RUNNING to FINAL_SAVING
2018-02-23 19:39:14,787 INFO org.apache.hadoop.yarn.server.resourcemanager.rmapp.RMAppImpl: Updating application application_1519385105809_0001 with final state: FINISHING
2018-02-23 19:39:14,788 INFO org.apache.hadoop.yarn.server.resourcemanager.rmapp.RMAppImpl: application_1519385105809_0001 State change from RUNNING to FINAL_SAVING
2018-02-23 19:39:14,788 INFO org.apache.hadoop.yarn.server.resourcemanager.recovery.RMStateStore: Updating info for app: application_1519385105809_0001
2018-02-23 19:39:14,788 INFO org.apache.hadoop.yarn.server.resourcemanager.rmapp.attempt.RMAppAttemptImpl: appattempt_1519385105809_0001_000001 State change from FINAL_SAVING to FINISHING
2018-02-23 19:39:14,788 INFO org.apache.hadoop.yarn.server.resourcemanager.rmapp.RMAppImpl: application_1519385105809_0001 State change from FINAL_SAVING to FINISHING
2018-02-23 19:39:15,522 INFO org.apache.hadoop.yarn.server.resourcemanager.rmcontainer.RMContainerImpl: container_1519385105809_0001_01_000003 Container Transitioned from RUNNING to COMPLETED
2018-02-23 19:39:15,522 INFO org.apache.hadoop.yarn.server.resourcemanager.scheduler.common.fica.FiCaSchedulerApp: Completed container: container_1519385105809_0001_01_000003 in state: COMPLETED event:FINISHED
2018-02-23 19:39:15,523 INFO org.apache.hadoop.yarn.server.resourcemanager.RMAuditLogger: USER=root	OPERATION=AM Released Container	TARGET=SchedulerApp	RESULT=SUCCESS	APPID=application_1519385105809_0001	CONTAINERID=container_1519385105809_0001_01_000003
2018-02-23 19:39:15,523 INFO org.apache.hadoop.yarn.server.resourcemanager.scheduler.SchedulerNode: Released container container_1519385105809_0001_01_000003 of capacity <memory:1024, vCores:1> on host ustc-OptiPlex-7050:46541, which currently has 1 containers, <memory:2048, vCores:1> used and <memory:6144, vCores:7> available, release resources=true
2018-02-23 19:39:15,523 INFO org.apache.hadoop.yarn.server.resourcemanager.scheduler.capacity.LeafQueue: default used=<memory:2048, vCores:1> numContainers=1 user=root user-resources=<memory:2048, vCores:1>
2018-02-23 19:39:15,523 INFO org.apache.hadoop.yarn.server.resourcemanager.scheduler.capacity.LeafQueue: completedContainer container=Container: [ContainerId: container_1519385105809_0001_01_000003, NodeId: ustc-OptiPlex-7050:46541, NodeHttpAddress: ustc-OptiPlex-7050:8042, Resource: <memory:1024, vCores:1>, Priority: 10, Token: Token { kind: ContainerToken, service: 127.0.1.1:46541 }, ] queue=default: capacity=1.0, absoluteCapacity=1.0, usedResources=<memory:2048, vCores:1>, usedCapacity=0.25, absoluteUsedCapacity=0.25, numApps=1, numContainers=1 cluster=<memory:8192, vCores:8>
2018-02-23 19:39:15,524 INFO org.apache.hadoop.yarn.server.resourcemanager.scheduler.capacity.ParentQueue: completedContainer queue=root usedCapacity=0.25 absoluteUsedCapacity=0.25 used=<memory:2048, vCores:1> cluster=<memory:8192, vCores:8>
2018-02-23 19:39:15,524 INFO org.apache.hadoop.yarn.server.resourcemanager.scheduler.capacity.ParentQueue: Re-sorting completed queue: root.default stats: default: capacity=1.0, absoluteCapacity=1.0, usedResources=<memory:2048, vCores:1>, usedCapacity=0.25, absoluteUsedCapacity=0.25, numApps=1, numContainers=1
2018-02-23 19:39:15,524 INFO org.apache.hadoop.yarn.server.resourcemanager.scheduler.capacity.CapacityScheduler: Application attempt appattempt_1519385105809_0001_000001 released container container_1519385105809_0001_01_000003 on node: host: ustc-OptiPlex-7050:46541 #containers=1 available=<memory:6144, vCores:7> used=<memory:2048, vCores:1> with event: FINISHED
2018-02-23 19:39:15,793 INFO org.apache.hadoop.yarn.server.resourcemanager.ApplicationMasterService: application_1519385105809_0001 unregistered successfully. 
2018-02-23 19:39:21,530 INFO org.apache.hadoop.yarn.server.resourcemanager.rmcontainer.RMContainerImpl: container_1519385105809_0001_01_000001 Container Transitioned from RUNNING to COMPLETED
2018-02-23 19:39:21,530 INFO org.apache.hadoop.yarn.server.resourcemanager.scheduler.common.fica.FiCaSchedulerApp: Completed container: container_1519385105809_0001_01_000001 in state: COMPLETED event:FINISHED
2018-02-23 19:39:21,530 INFO org.apache.hadoop.yarn.server.resourcemanager.ApplicationMasterService: Unregistering app attempt : appattempt_1519385105809_0001_000001
2018-02-23 19:39:21,530 INFO org.apache.hadoop.yarn.server.resourcemanager.RMAuditLogger: USER=root	OPERATION=AM Released Container	TARGET=SchedulerApp	RESULT=SUCCESS	APPID=application_1519385105809_0001	CONTAINERID=container_1519385105809_0001_01_000001
2018-02-23 19:39:21,531 INFO org.apache.hadoop.yarn.server.resourcemanager.scheduler.SchedulerNode: Released container container_1519385105809_0001_01_000001 of capacity <memory:2048, vCores:1> on host ustc-OptiPlex-7050:46541, which currently has 0 containers, <memory:0, vCores:0> used and <memory:8192, vCores:8> available, release resources=true
2018-02-23 19:39:21,531 INFO org.apache.hadoop.yarn.server.resourcemanager.scheduler.capacity.LeafQueue: default used=<memory:0, vCores:0> numContainers=0 user=root user-resources=<memory:0, vCores:0>
2018-02-23 19:39:21,531 INFO org.apache.hadoop.yarn.server.resourcemanager.scheduler.capacity.LeafQueue: completedContainer container=Container: [ContainerId: container_1519385105809_0001_01_000001, NodeId: ustc-OptiPlex-7050:46541, NodeHttpAddress: ustc-OptiPlex-7050:8042, Resource: <memory:2048, vCores:1>, Priority: 0, Token: Token { kind: ContainerToken, service: 127.0.1.1:46541 }, ] queue=default: capacity=1.0, absoluteCapacity=1.0, usedResources=<memory:0, vCores:0>, usedCapacity=0.0, absoluteUsedCapacity=0.0, numApps=1, numContainers=0 cluster=<memory:8192, vCores:8>
2018-02-23 19:39:21,531 INFO org.apache.hadoop.yarn.server.resourcemanager.scheduler.capacity.ParentQueue: completedContainer queue=root usedCapacity=0.0 absoluteUsedCapacity=0.0 used=<memory:0, vCores:0> cluster=<memory:8192, vCores:8>
2018-02-23 19:39:21,531 INFO org.apache.hadoop.yarn.server.resourcemanager.scheduler.capacity.ParentQueue: Re-sorting completed queue: root.default stats: default: capacity=1.0, absoluteCapacity=1.0, usedResources=<memory:0, vCores:0>, usedCapacity=0.0, absoluteUsedCapacity=0.0, numApps=1, numContainers=0
2018-02-23 19:39:21,531 INFO org.apache.hadoop.yarn.server.resourcemanager.scheduler.capacity.CapacityScheduler: Application attempt appattempt_1519385105809_0001_000001 released container container_1519385105809_0001_01_000001 on node: host: ustc-OptiPlex-7050:46541 #containers=0 available=<memory:8192, vCores:8> used=<memory:0, vCores:0> with event: FINISHED
2018-02-23 19:39:21,531 INFO org.apache.hadoop.yarn.server.resourcemanager.security.AMRMTokenSecretManager: Application finished, removing password for appattempt_1519385105809_0001_000001
2018-02-23 19:39:21,532 INFO org.apache.hadoop.yarn.server.resourcemanager.rmapp.attempt.RMAppAttemptImpl: appattempt_1519385105809_0001_000001 State change from FINISHING to FINISHED
2018-02-23 19:39:21,534 INFO org.apache.hadoop.yarn.server.resourcemanager.rmapp.RMAppImpl: application_1519385105809_0001 State change from FINISHING to FINISHED
2018-02-23 19:39:21,534 INFO org.apache.hadoop.yarn.server.resourcemanager.scheduler.capacity.CapacityScheduler: Application Attempt appattempt_1519385105809_0001_000001 is done. finalState=FINISHED
2018-02-23 19:39:21,534 INFO org.apache.hadoop.yarn.server.resourcemanager.scheduler.AppSchedulingInfo: Application application_1519385105809_0001 requests cleared
2018-02-23 19:39:21,534 INFO org.apache.hadoop.yarn.server.resourcemanager.scheduler.capacity.LeafQueue: Application removed - appId: application_1519385105809_0001 user: root queue: default #user-pending-applications: 0 #user-active-applications: 0 #queue-pending-applications: 0 #queue-active-applications: 0
2018-02-23 19:39:21,535 INFO org.apache.hadoop.yarn.server.resourcemanager.amlauncher.AMLauncher: Cleaning master appattempt_1519385105809_0001_000001
2018-02-23 19:39:21,535 INFO org.apache.hadoop.yarn.server.resourcemanager.RMAuditLogger: USER=root	OPERATION=Application Finished - Succeeded	TARGET=RMAppManager	RESULT=SUCCESS	APPID=application_1519385105809_0001
2018-02-23 19:39:21,535 INFO org.apache.hadoop.yarn.server.resourcemanager.scheduler.capacity.ParentQueue: Application removed - appId: application_1519385105809_0001 user: root leaf-queue of parent: root #applications: 0
2018-02-23 19:39:21,538 INFO org.apache.hadoop.yarn.server.resourcemanager.RMAppManager$ApplicationSummary: appId=application_1519385105809_0001,name=word count,user=root,queue=default,state=FINISHED,trackingUrl=http://ustc-OptiPlex-7050:8088/proxy/application_1519385105809_0001/,appMasterHost=ustc-optiplex-7050,startTime=1519385943560,finishTime=1519385954787,finalStatus=SUCCEEDED,memorySeconds=42722,vcoreSeconds=22,preemptedAMContainers=0,preemptedNonAMContainers=0,preemptedResources=<memory:0\, vCores:0>,applicationType=MAPREDUCE
2018-02-23 19:39:22,554 INFO org.apache.hadoop.yarn.server.resourcemanager.scheduler.capacity.CapacityScheduler: Null container completed...
2018-02-23 21:16:38,648 ERROR org.apache.hadoop.yarn.server.resourcemanager.ResourceManager: RECEIVED SIGNAL 15: SIGTERM
2018-02-23 21:16:38,685 ERROR org.apache.hadoop.security.token.delegation.AbstractDelegationTokenSecretManager: ExpiredTokenRemover received java.lang.InterruptedException: sleep interrupted
2018-02-23 21:16:38,685 INFO org.mortbay.log: Stopped HttpServer2$SelectChannelConnectorWithSafeStartup@0.0.0.0:8088
2018-02-23 21:16:38,687 INFO org.apache.hadoop.ipc.Server: Stopping server on 8032
2018-02-23 21:16:38,689 INFO org.apache.hadoop.ipc.Server: Stopping IPC Server listener on 8032
2018-02-23 21:16:38,689 INFO org.apache.hadoop.ipc.Server: Stopping IPC Server Responder
2018-02-23 21:16:38,690 INFO org.apache.hadoop.ipc.Server: Stopping server on 8033
2018-02-23 21:16:38,690 INFO org.apache.hadoop.ipc.Server: Stopping IPC Server listener on 8033
2018-02-23 21:16:38,690 INFO org.apache.hadoop.ipc.Server: Stopping IPC Server Responder
2018-02-23 21:16:38,690 INFO org.apache.hadoop.yarn.server.resourcemanager.ResourceManager: Transitioning to standby state
2018-02-23 21:16:38,690 WARN org.apache.hadoop.yarn.server.resourcemanager.amlauncher.ApplicationMasterLauncher: org.apache.hadoop.yarn.server.resourcemanager.amlauncher.ApplicationMasterLauncher$LauncherThread interrupted. Returning.
2018-02-23 21:16:38,691 INFO org.apache.hadoop.ipc.Server: Stopping server on 8030
2018-02-23 21:16:38,692 INFO org.apache.hadoop.ipc.Server: Stopping IPC Server listener on 8030
2018-02-23 21:16:38,692 INFO org.apache.hadoop.ipc.Server: Stopping server on 8031
2018-02-23 21:16:38,692 INFO org.apache.hadoop.ipc.Server: Stopping IPC Server Responder
2018-02-23 21:16:38,694 INFO org.apache.hadoop.ipc.Server: Stopping IPC Server Responder
2018-02-23 21:16:38,694 INFO org.apache.hadoop.yarn.util.AbstractLivelinessMonitor: NMLivelinessMonitor thread interrupted
2018-02-23 21:16:38,694 INFO org.apache.hadoop.ipc.Server: Stopping IPC Server listener on 8031
2018-02-23 21:16:38,694 ERROR org.apache.hadoop.yarn.server.resourcemanager.ResourceManager: Returning, interrupted : java.lang.InterruptedException
2018-02-23 21:16:38,695 INFO org.apache.hadoop.yarn.event.AsyncDispatcher: AsyncDispatcher is draining to stop, igonring any new events.
2018-02-23 21:16:38,696 INFO org.apache.hadoop.yarn.util.AbstractLivelinessMonitor: AMLivelinessMonitor thread interrupted
2018-02-23 21:16:38,699 INFO org.apache.hadoop.yarn.util.AbstractLivelinessMonitor: org.apache.hadoop.yarn.server.resourcemanager.rmcontainer.ContainerAllocationExpirer thread interrupted
2018-02-23 21:16:38,697 INFO org.apache.hadoop.yarn.util.AbstractLivelinessMonitor: AMLivelinessMonitor thread interrupted
2018-02-23 21:16:38,699 ERROR org.apache.hadoop.security.token.delegation.AbstractDelegationTokenSecretManager: ExpiredTokenRemover received java.lang.InterruptedException: sleep interrupted
2018-02-23 21:16:38,726 INFO org.apache.hadoop.metrics2.impl.MetricsSystemImpl: Stopping ResourceManager metrics system...
2018-02-23 21:16:38,726 INFO org.apache.hadoop.metrics2.impl.MetricsSystemImpl: ResourceManager metrics system stopped.
2018-02-23 21:16:38,727 INFO org.apache.hadoop.metrics2.impl.MetricsSystemImpl: ResourceManager metrics system shutdown complete.
2018-02-23 21:16:38,727 INFO org.apache.hadoop.yarn.event.AsyncDispatcher: AsyncDispatcher is draining to stop, igonring any new events.
2018-02-23 21:16:38,727 INFO org.apache.hadoop.yarn.server.resourcemanager.ResourceManager: Transitioned to standby state
2018-02-23 21:16:38,727 INFO org.apache.hadoop.yarn.server.resourcemanager.ResourceManager: SHUTDOWN_MSG: 
/************************************************************
SHUTDOWN_MSG: Shutting down ResourceManager at ustc-optiplex-7050/127.0.1.1
************************************************************/
